Workbook

Sheet Dashboard
A1: 5s30s Steepener — Easing-Cycle Backtest & Tenor Validation
A2: Companion quant workbook to the Q4 trade memo (macro-trade-framework branch)
A3: Last updated: 2026-08-29 (curve as of H.15 Aug-27/28-2026)
A5: HEADLINE FINDINGS (live links to 'Cycle Backtest')
A6: Cycles tested (1984-2025) | B6: =COUNTA('Cycle Backtest'!A5:A12)
A7: Hit rate, D+12m > 0 | B7: ='Cycle Backtest'!B16
A8: Median D+12m, all cycles (bp) | B8: ='Cycle Backtest'!B15
A9: Median peak D, deep cycles (bp) | B9: ='Cycle Backtest'!B19
A10: Median months to peak | B10: ='Cycle Backtest'!B20
A11: Worst 12m outcome (1998: cuts then re-hike) | B11: ='Cycle Backtest'!B18
A12: Median pre-positioning gain (T-6m to T0) | B12: ='Cycle Backtest'!B21
A13: 2s30s / 10s30s peak beta vs 5s30s | B13: =TEXT('Cycle Backtest'!B22,"0.00")&"x / "&TEXT('Cycle Backtest'!B23,"0.00")&"x"
A15: WHAT THE BACKTEST SAYS ABOUT THE TRADE
A16: 1. Steepeners are cycle trades: every deep easing cycle (1989-92, 2001-03, 2007-10, and the COVID extension) delivered +180 to +230bp peaks vs T0 — but the median peak arrives ~18 months after the first cut. Positive carry matters.
A17: 2. The failure mode is the shallow/insurance cycle: 1995 went nowhere; 1998 lost 50bp within 12m when the Fed re-hiked. That is exactly the scenario the memo's stop (+45-50bp level) and Board-vote falsifier are built around.
A18: 3. Pre-positioning before the first cut historically paid (median +33bp from T-6m into T0) — but today's entry is 23 months into a PAUSED cycle with hike pricing: the honest analogs split between 1990 (pause, then recession, then mega-steepening) and 1998-99 (re-hike, then flattening). The labor market is the differentiator — per the memo's Q1.
A19: 4. Target calibration: initial target +110-120 means regaining the 2025 steepness (peak ~+110) — requires only that cuts resume, not a recession. The +150 stretch sits BELOW every deep-cycle peak LEVEL (+170 to +295) — conservative if the cycle turns out deep.
A20: 5. Tenor choice: 2s30s captured ~1.6x of 5s30s's peak but needs ~2x the balance sheet and its carry IS the Fed bet; 10s30s kept only ~0.33x. 5s30s: ~62% of the payoff, ~half the gross, positive carry that isn't purely the hike premium.
A22: REVISED TRADE PARAMETERS (post-validation)
A23: Entry (5s30s) | B23: +75 to +80bp (H.15 Aug-27: +81; post-Warsh flattening)
A24: Initial target | B24: +110 to +120bp
A25: Stretch target | B25: +150bp (deep-cycle scenario only)
A26: Stop | B26: +45 to +50bp
A27: Sizing | B27: DV01-neutral, $20k/bp per leg; futures legs sized dynamically off current CTD DV01s
A28: Carry + roll | B28: ~ +10bp/yr (aged-bond repricing, curve unchanged; assumption-sensitive, sign robust)
A30: Method & caveats: quarterly checkpoints understate intra-month extremes; 1984-86 data +/-25-30bp; 30y after Feb-2002 is a long-bond proxy (issuance gap). Scenario probabilities in the memo are subjective priors, not outputs of this backtest. Re-run backtest_5s30s_easing_cycles.py against daily FRED DGS2/DGS5/DGS10/DGS30 CSVs for exact levels when network access allows.

Sheet Yield Data
A1: Checkpoint yields around Fed easing cycles (CMT, %)
A2: BLUE = input data. Quarterly month-end approximations reconstructed from the historical record (primary source is FRED H.15 daily CMTs; this sandbox had no network access to FRED, so values carry the per-cycle tolerance flagged on 'Cycle Backtest'). Peaks cross-checked against published anchors: post-GFC 5s30s peak ~+280-300bp; Jun-2025 +101bp 'steepest since 2021'. The +23m row of the 2024-25 cycle is official H.15 Aug-27-2026.
A3: Cycle | B3: Offset (m) | C3: 2y | D3: 5y | E3: 10y | F3: 30y | G3: 2s30s (bp) | H3: 5s30s (bp) | I3: 10s30s (bp) | J3: d2s30s vs T0 | K3: d5s30s vs T0 | L3: d10s30s vs T0
A4: 1984 disinflation | B4: -6 | C4: 11.85 | D4: 12.25 | E4: 12.35 | F4: 12.4 | G4: =(F4-C4)*100 | H4: =(F4-D4)*100 | I4: =(F4-E4)*100 | J4: =G4-G$5 | K4: =H4-H$5 | L4: =I4-I$5
A5: 1984 disinflation | B5: 0 | C5: 11.6 | D5: 12 | E5: 12.3 | F5: 12.3 | G5: =(F5-C5)*100 | H5: =(F5-D5)*100 | I5: =(F5-E5)*100 | J5: =G5-G$5 | K5: =H5-H$5 | L5: =I5-I$5
A6: 1984 disinflation | B6: 3 | C6: 9.7 | D6: 10.8 | E6: 11.5 | F6: 11.6 | G6: =(F6-C6)*100 | H6: =(F6-D6)*100 | I6: =(F6-E6)*100 | J6: =G6-G$5 | K6: =H6-H$5 | L6: =I6-I$5
A7: 1984 disinflation | B7: 6 | C7: 10.3 | D7: 11.1 | E7: 11.9 | F7: 11.9 | G7: =(F7-C7)*100 | H7: =(F7-D7)*100 | I7: =(F7-E7)*100 | J7: =G7-G$5 | K7: =H7-H$5 | L7: =I7-I$5
A8: 1984 disinflation | B8: 9 | C8: 8.6 | D8: 9.4 | E8: 10.3 | F8: 10.5 | G8: =(F8-C8)*100 | H8: =(F8-D8)*100 | I8: =(F8-E8)*100 | J8: =G8-G$5 | K8: =H8-H$5 | L8: =I8-I$5
A9: 1984 disinflation | B9: 12 | C9: 8.8 | D9: 9.5 | E9: 10.4 | F9: 10.7 | G9: =(F9-C9)*100 | H9: =(F9-D9)*100 | I9: =(F9-E9)*100 | J9: =G9-G$5 | K9: =H9-H$5 | L9: =I9-I$5
A10: 1984 disinflation | B10: 18 | C10: 7.1 | D10: 7.45 | E10: 7.8 | F10: 7.95 | G10: =(F10-C10)*100 | H10: =(F10-D10)*100 | I10: =(F10-E10)*100 | J10: =G10-G$5 | K10: =H10-H$5 | L10: =I10-I$5
A11: 1984 disinflation | B11: 24 | C11: 6.3 | D11: 6.9 | E11: 7.45 | F11: 7.6 | G11: =(F11-C11)*100 | H11: =(F11-D11)*100 | I11: =(F11-E11)*100 | J11: =G11-G$5 | K11: =H11-H$5 | L11: =I11-I$5
A12: 1984 disinflation | B12: 30 | C12: 6.5 | D12: 7 | E12: 7.25 | F12: 7.55 | G12: =(F12-C12)*100 | H12: =(F12-D12)*100 | I12: =(F12-E12)*100 | J12: =G12-G$5 | K12: =H12-H$5 | L12: =I12-I$5
A13: 1989-92 S&L / recession | B13: -6 | C13: 9.25 | D13: 9.2 | E13: 9.15 | F13: 9 | G13: =(F13-C13)*100 | H13: =(F13-D13)*100 | I13: =(F13-E13)*100 | J13: =G13-G$14 | K13: =H13-H$14 | L13: =I13-I$14
A14: 1989-92 S&L / recession | B14: 0 | C14: 8.45 | D14: 8.3 | E14: 8.3 | F14: 8.2 | G14: =(F14-C14)*100 | H14: =(F14-D14)*100 | I14: =(F14-E14)*100 | J14: =G14-G$14 | K14: =H14-H$14 | L14: =I14-I$14
A15: 1989-92 S&L / recession | B15: 3 | C15: 8.6 | D15: 8.5 | E15: 8.35 | F15: 8.25 | G15: =(F15-C15)*100 | H15: =(F15-D15)*100 | I15: =(F15-E15)*100 | J15: =G15-G$14 | K15: =H15-H$14 | L15: =I15-I$14
A16: 1989-92 S&L / recession | B16: 6 | C16: 7.8 | D16: 7.75 | E16: 7.9 | F16: 7.95 | G16: =(F16-C16)*100 | H16: =(F16-D16)*100 | I16: =(F16-E16)*100 | J16: =G16-G$14 | K16: =H16-H$14 | L16: =I16-I$14
A17: 1989-92 S&L / recession | B17: 9 | C17: 8.6 | D17: 8.6 | E17: 8.6 | F17: 8.6 | G17: =(F17-C17)*100 | H17: =(F17-D17)*100 | I17: =(F17-E17)*100 | J17: =G17-G$14 | K17: =H17-H$14 | L17: =I17-I$14
A18: 1989-92 S&L / recession | B18: 12 | C18: 8.2 | D18: 8.4 | E18: 8.4 | F18: 8.4 | G18: =(F18-C18)*100 | H18: =(F18-D18)*100 | I18: =(F18-E18)*100 | J18: =G18-G$14 | K18: =H18-H$14 | L18: =I18-I$14
A19: 1989-92 S&L / recession | B19: 18 | C19: 7.2 | D19: 7.7 | E19: 8.1 | F19: 8.25 | G19: =(F19-C19)*100 | H19: =(F19-D19)*100 | I19: =(F19-E19)*100 | J19: =G19-G$14 | K19: =H19-H$14 | L19: =I19-I$14
A20: 1989-92 S&L / recession | B20: 24 | C20: 6.8 | D20: 7.85 | E20: 8.2 | F20: 8.45 | G20: =(F20-C20)*100 | H20: =(F20-D20)*100 | I20: =(F20-E20)*100 | J20: =G20-G$14 | K20: =H20-H$14 | L20: =I20-I$14
A21: 1989-92 S&L / recession | B21: 30 | C21: 4.9 | D21: 6 | E21: 6.7 | F21: 7.4 | G21: =(F21-C21)*100 | H21: =(F21-D21)*100 | I21: =(F21-E21)*100 | J21: =G21-G$14 | K21: =H21-H$14 | L21: =I21-I$14
A22: 1989-92 S&L / recession | B22: 36 | C22: 4.7 | D22: 5.85 | E22: 6.9 | F22: 7.55 | G22: =(F22-C22)*100 | H22: =(F22-D22)*100 | I22: =(F22-E22)*100 | J22: =G22-G$14 | K22: =H22-H$14 | L22: =I22-I$14
A23: 1989-92 S&L / recession | B23: 42 | C23: 4.55 | D23: 6.05 | E23: 6.75 | F23: 7.4 | G23: =(F23-C23)*100 | H23: =(F23-D23)*100 | I23: =(F23-E23)*100 | J23: =G23-G$14 | K23: =H23-H$14 | L23: =I23-I$14
A24: 1995 mid-cycle | B24: -6 | C24: 7.4 | D24: 7.7 | E24: 7.75 | F24: 7.9 | G24: =(F24-C24)*100 | H24: =(F24-D24)*100 | I24: =(F24-E24)*100 | J24: =G24-G$25 | K24: =H24-H$25 | L24: =I24-I$25
A25: 1995 mid-cycle | B25: 0 | C25: 5.85 | D25: 6 | E25: 6.3 | F25: 6.6 | G25: =(F25-C25)*100 | H25: =(F25-D25)*100 | I25: =(F25-E25)*100 | J25: =G25-G$25 | K25: =H25-H$25 | L25: =I25-I$25
A26: 1995 mid-cycle | B26: 3 | C26: 5.6 | D26: 5.8 | E26: 6 | F26: 6.3 | G26: =(F26-C26)*100 | H26: =(F26-D26)*100 | I26: =(F26-E26)*100 | J26: =G26-G$25 | K26: =H26-H$25 | L26: =I26-I$25
A27: 1995 mid-cycle | B27: 6 | C27: 5.15 | D27: 5.35 | E27: 5.6 | F27: 6 | G27: =(F27-C27)*100 | H27: =(F27-D27)*100 | I27: =(F27-E27)*100 | J27: =G27-G$25 | K27: =H27-H$25 | L27: =I27-I$25
A28: 1995 mid-cycle | B28: 9 | C28: 5.95 | D28: 6.3 | E28: 6.5 | F28: 6.8 | G28: =(F28-C28)*100 | H28: =(F28-D28)*100 | I28: =(F28-E28)*100 | J28: =G28-G$25 | K28: =H28-H$25 | L28: =I28-I$25
A29: 1995 mid-cycle | B29: 12 | C29: 6.1 | D29: 6.45 | E29: 6.75 | F29: 7 | G29: =(F29-C29)*100 | H29: =(F29-D29)*100 | I29: =(F29-E29)*100 | J29: =G29-G$25 | K29: =H29-H$25 | L29: =I29-I$25
A30: 1995 mid-cycle | B30: 18 | C30: 5.9 | D30: 6.25 | E30: 6.5 | F30: 6.8 | G30: =(F30-C30)*100 | H30: =(F30-D30)*100 | I30: =(F30-E30)*100 | J30: =G30-G$25 | K30: =H30-H$25 | L30: =I30-I$25
A31: 1995 mid-cycle | B31: 24 | C31: 5.9 | D31: 6 | E31: 6.2 | F31: 6.5 | G31: =(F31-C31)*100 | H31: =(F31-D31)*100 | I31: =(F31-E31)*100 | J31: =G31-G$25 | K31: =H31-H$25 | L31: =I31-I$25
A32: 1998 LTCM insurance | B32: -6 | C32: 5.55 | D32: 5.6 | E32: 5.65 | F32: 5.95 | G32: =(F32-C32)*100 | H32: =(F32-D32)*100 | I32: =(F32-E32)*100 | J32: =G32-G$33 | K32: =H32-H$33 | L32: =I32-I$33
A33: 1998 LTCM insurance | B33: 0 | C33: 4.3 | D33: 4.2 | E33: 4.4 | F33: 5 | G33: =(F33-C33)*100 | H33: =(F33-D33)*100 | I33: =(F33-E33)*100 | J33: =G33-G$33 | K33: =H33-H$33 | L33: =I33-I$33
A34: 1998 LTCM insurance | B34: 3 | C34: 4.55 | D34: 4.55 | E34: 4.65 | F34: 5.1 | G34: =(F34-C34)*100 | H34: =(F34-D34)*100 | I34: =(F34-E34)*100 | J34: =G34-G$33 | K34: =H34-H$33 | L34: =I34-I$33
A35: 1998 LTCM insurance | B35: 6 | C35: 5.05 | D35: 5.1 | E35: 5.25 | F35: 5.6 | G35: =(F35-C35)*100 | H35: =(F35-D35)*100 | I35: =(F35-E35)*100 | J35: =G35-G$33 | K35: =H35-H$33 | L35: =I35-I$33
A36: 1998 LTCM insurance | B36: 12 | C36: 5.65 | D36: 5.75 | E36: 5.9 | F36: 6.05 | G36: =(F36-C36)*100 | H36: =(F36-D36)*100 | I36: =(F36-E36)*100 | J36: =G36-G$33 | K36: =H36-H$33 | L36: =I36-I$33
A37: 2001-03 dot-com | B37: -6 | C37: 6.3 | D37: 6.15 | E37: 6.05 | F37: 5.9 | G37: =(F37-C37)*100 | H37: =(F37-D37)*100 | I37: =(F37-E37)*100 | J37: =G37-G$38 | K37: =H37-H$38 | L37: =I37-I$38
A38: 2001-03 dot-com | B38: 0 | C38: 4.9 | D38: 4.9 | E38: 5.1 | F38: 5.45 | G38: =(F38-C38)*100 | H38: =(F38-D38)*100 | I38: =(F38-E38)*100 | J38: =G38-G$38 | K38: =H38-H$38 | L38: =I38-I$38
A39: 2001-03 dot-com | B39: 3 | C39: 4.25 | D39: 4.75 | E39: 5.3 | F39: 5.8 | G39: =(F39-C39)*100 | H39: =(F39-D39)*100 | I39: =(F39-E39)*100 | J39: =G39-G$38 | K39: =H39-H$38 | L39: =I39-I$38
A40: 2001-03 dot-com | B40: 6 | C40: 3.8 | D40: 4.6 | E40: 5.05 | F40: 5.5 | G40: =(F40-C40)*100 | H40: =(F40-D40)*100 | I40: =(F40-E40)*100 | J40: =G40-G$38 | K40: =H40-H$38 | L40: =I40-I$38
...

Sheet Cycle Backtest
A1: 5s30s steepener across Fed easing cycles — entry at first cut (T0), bp of curve
A2: All results computed by formula from 'Yield Data'. Quarterly checkpoints understate intra-month peaks slightly.
A4: Cycle | B4: First cut | C4: Cycle kind | D4: Data quality | E4: Funds start % | F4: Funds trough % | G4: Cuts (bp) | H4: 5s30s @T0 | I4: T-6m to T0 gain | J4: D +6m | K4: D +12m | L4: D +24m | M4: Peak D | N4: @ month | O4: Worst D | P4: Peak D 2s30s | Q4: Peak D 10s30s
A5: 1984 disinflation | B5: 1984-09 | C5: deep (no recession: disinflation easing) | D5: era~ (±25-30bp) | E5: 11.5 | F5: 5.875 | G5: =(E5-F5)*100 | H5: ='Yield Data'!H5 | I5: ='Yield Data'!H5-'Yield Data'!H4 | J5: ='Yield Data'!K7 | K5: ='Yield Data'!K9 | L5: ='Yield Data'!K11 | M5: =MAX('Yield Data'!K5:K12) | N5: =INDEX('Yield Data'!B5:B12,MATCH(M5,'Yield Data'!K5:K12,0)) | O5: =MIN('Yield Data'!K5:K12) | P5: =MAX('Yield Data'!J5:J12) | Q5: =MAX('Yield Data'!L5:L12)
A6: 1989-92 S&L / recession | B6: 1989-06 | C6: deep (recession Jul90-Mar91) | D6: ok (±10-15bp) | E6: 9.8125 | F6: 3 | G6: =(E6-F6)*100 | H6: ='Yield Data'!H14 | I6: ='Yield Data'!H14-'Yield Data'!H13 | J6: ='Yield Data'!K16 | K6: ='Yield Data'!K18 | L6: ='Yield Data'!K20 | M6: =MAX('Yield Data'!K14:K23) | N6: =INDEX('Yield Data'!B14:B23,MATCH(M6,'Yield Data'!K14:K23,0)) | O6: =MIN('Yield Data'!K14:K23) | P6: =MAX('Yield Data'!J14:J23) | Q6: =MAX('Yield Data'!L14:L23)
A7: 1995 mid-cycle | B7: 1995-07 | C7: shallow (3 cuts, no recession) | D7: ok (±10-15bp) | E7: 6 | F7: 5.25 | G7: =(E7-F7)*100 | H7: ='Yield Data'!H25 | I7: ='Yield Data'!H25-'Yield Data'!H24 | J7: ='Yield Data'!K27 | K7: ='Yield Data'!K29 | L7: ='Yield Data'!K31 | M7: =MAX('Yield Data'!K25:K31) | N7: =INDEX('Yield Data'!B25:B31,MATCH(M7,'Yield Data'!K25:K31,0)) | O7: =MIN('Yield Data'!K25:K31) | P7: =MAX('Yield Data'!J25:J31) | Q7: =MAX('Yield Data'!L25:L31)
A8: 1998 LTCM insurance | B8: 1998-09 | C8: shallow (3 cuts, then RE-HIKED Jun-1999) | D8: ok (±10-15bp) | E8: 5.5 | F8: 4.75 | G8: =(E8-F8)*100 | H8: ='Yield Data'!H33 | I8: ='Yield Data'!H33-'Yield Data'!H32 | J8: ='Yield Data'!K35 | K8: ='Yield Data'!K36 | L8: n/a | M8: =MAX('Yield Data'!K33:K36) | N8: =INDEX('Yield Data'!B33:B36,MATCH(M8,'Yield Data'!K33:K36,0)) | O8: =MIN('Yield Data'!K33:K36) | P8: =MAX('Yield Data'!J33:J36) | Q8: =MAX('Yield Data'!L33:L36)
A9: 2001-03 dot-com | B9: 2001-01 | C9: deep (recession Mar-Nov 2001) | D9: ok; 30y gap~ after Feb-2002 (long-bond proxy) | E9: 6.5 | F9: 1 | G9: =(E9-F9)*100 | H9: ='Yield Data'!H38 | I9: ='Yield Data'!H38-'Yield Data'!H37 | J9: ='Yield Data'!K40 | K9: ='Yield Data'!K42 | L9: ='Yield Data'!K44 | M9: =MAX('Yield Data'!K38:K45) | N9: =INDEX('Yield Data'!B38:B45,MATCH(M9,'Yield Data'!K38:K45,0)) | O9: =MIN('Yield Data'!K38:K45) | P9: =MAX('Yield Data'!J38:J45) | Q9: =MAX('Yield Data'!L38:L45)
A10: 2007-08 GFC | B10: 2007-09 | C10: deep (recession Dec07-Jun09; ZIRP + QE follow-on) | D10: ok (±10-15bp) | E10: 5.25 | F10: 0.125 | G10: =(E10-F10)*100 | H10: ='Yield Data'!H47 | I10: ='Yield Data'!H47-'Yield Data'!H46 | J10: ='Yield Data'!K49 | K10: ='Yield Data'!K51 | L10: ='Yield Data'!K54 | M10: =MAX('Yield Data'!K47:K56) | N10: =INDEX('Yield Data'!B47:B56,MATCH(M10,'Yield Data'!K47:K56,0)) | O10: =MIN('Yield Data'!K47:K56) | P10: =MAX('Yield Data'!J47:J56) | Q10: =MAX('Yield Data'!L47:L56)
A11: 2019-20 mid-cycle + COVID | B11: 2019-07 | C11: shallow->deep (COVID forced it deep in Mar-2020) | D11: ok (±5-10bp) | E11: 2.375 | F11: 0.125 | G11: =(E11-F11)*100 | H11: ='Yield Data'!H58 | I11: ='Yield Data'!H58-'Yield Data'!H57 | J11: ='Yield Data'!K60 | K11: ='Yield Data'!K62 | L11: ='Yield Data'!K65 | M11: =MAX('Yield Data'!K58:K65) | N11: =INDEX('Yield Data'!B58:B65,MATCH(M11,'Yield Data'!K58:K65,0)) | O11: =MIN('Yield Data'!K58:K65) | P11: =MAX('Yield Data'!J58:J65) | Q11: =MAX('Yield Data'!L58:L65)
A12: 2024-25 (current cycle) | B12: 2024-09 | C12: gradual (cuts 2024-25, PAUSED 2026 with hike pricing) | D12: ok (±5-10bp); +23m = Aug-27-2026 official H.15 | E12: 5.375 | F12: 3.625 | G12: =(E12-F12)*100 | H12: ='Yield Data'!H67 | I12: ='Yield Data'!H67-'Yield Data'!H66 | J12: ='Yield Data'!K69 | K12: ='Yield Data'!K71 | L12: n/a | M12: =MAX('Yield Data'!K67:K73) | N12: =INDEX('Yield Data'!B67:B73,MATCH(M12,'Yield Data'!K67:K73,0)) | O12: =MIN('Yield Data'!K67:K73) | P12: =MAX('Yield Data'!J67:J73) | Q12: =MAX('Yield Data'!L67:L73)
A14: SUMMARY
A15: Median D +12m (all cycles) | B15: =MEDIAN(K5:K12)
A16: Hit rate: D +12m > 0 | B16: =COUNTIF(K5:K12,">0")&" of "&COUNT(K5:K12)
A17: Hit rate: D +12m >= +30bp | B17: =COUNTIF(K5:K12,">=30")&" of "&COUNT(K5:K12)
A18: Worst D +12m (1998 re-hike) | B18: =MIN(K5:K12)
A19: Median peak D, deep cycles | B19: =MEDIAN(M5,M6,M9,M10,M11)
A20: Median months to peak (all) | B20: =MEDIAN(N5:N12)
A21: Median T-6m to T0 gain (pre-positioning) | B21: =MEDIAN(I5:I12)
A22: 2s30s peak beta vs 5s30s (deep median) | B22: =MEDIAN(P5/M5,P6/M6,P9/M9,P10/M10,P11/M11)
A23: 10s30s peak beta vs 5s30s (deep median) | B23: =MEDIAN(Q5/M5,Q6/M6,Q9/M9,Q10/M10,Q11/M11)

Sheet Tenor Comparison
A1: 2s30s vs 5s30s vs 10s30s — actual curve, Aug 27-28 2026
A2: Curve: official H.15 Aug-27-2026 where available; * = interpolated estimate (blue = editable input). Carry+roll here uses the duration approximation; carry_roll_tenor_comparison.py reprices aged par bonds exactly (differences <2bp/yr). At the 2y, static carry is mostly the priced hike premium — realized only if the Fed does not hike: there, carry IS the trade, not a bonus.
A5: Inputs
A6: Tenor | B6: Yield %
A7: 1y * | B7: 4.08
A8: 2y | B8: 4.24
A9: 3y * | B9: 4.29
A10: 5y | B10: 4.38
A11: 7y * | B11: 4.51
A12: 10y | B12: 4.67
A13: 20y | B13: 5.18
A14: 30y | B14: 5.19
A15: Repo / funding % | B15: 3.65
A16: DV01 per leg ($/bp) | B16: 20000
A17: Mod. duration, par bond: 2y / 5y / 10y / 30y | C17: 1.9 | D17: 4.45 | E17: 8.09 | F17: 15.17 | G17: semiannual par-bond pricing at input yields (see .py)
A18: Aged mod. duration: 1y / 4y / 9y / 29y | C18: 0.97 | D18: 3.63 | E18: 7.36 | F18: 14.9
A19: Aged yield (interp): 1y / 4y / 9y / 29y | C19: =B7 | D19: =(B9+B10)/2 | E19: =B11+(B12-B11)*2/3 | F19: =B13+(B14-B13)*0.9
A21: Pair | B21: Front yield % | C21: Front face $mm | D21: 30y face $mm | E21: Gross $mm | F21: Running carry $k/yr | G21: Roll $k/yr | H21: Carry+roll bp/yr | I21: Deep-cycle peak beta
A22: 2s30s | B22: =B8 | C22: =$B$16/(C17*100) | D22: =$B$16/($F$17*100) | E22: =C22+D22 | F22: =((B8-$B$15)*C22-(B14-$B$15)*D22)*10 | G22: =((B8-C19)*C18*C22-(B14-F19)*F18*D22)*10 | H22: =(F22+G22)*1000/$B$16 | I22: ='Cycle Backtest'!B22
A23: 5s30s | B23: =B10 | C23: =$B$16/(D17*100) | D23: =$B$16/($F$17*100) | E23: =C23+D23 | F23: =((B10-$B$15)*C23-(B14-$B$15)*D23)*10 | G23: =((B10-D19)*D18*C23-(B14-F19)*F18*D23)*10 | H23: =(F23+G23)*1000/$B$16 | I23: 1
A24: 10s30s | B24: =B12 | C24: =$B$16/(E17*100) | D24: =$B$16/($F$17*100) | E24: =C24+D24 | F24: =((B12-$B$15)*C24-(B14-$B$15)*D24)*10 | G24: =((B12-E19)*E18*C24-(B14-F19)*F18*D24)*10 | H24: =(F24+G24)*1000/$B$16 | I24: ='Cycle Backtest'!B23
A26: Reading: 5s30s delivers ~62% of 2s30s's historical cyclical payoff on ~half the balance sheet, with carry that is positive without being purely the hike-premium bet; 10s30s keeps only ~1/3 of the payoff. Futures legs (FV vs Ultra Bond) should be sized dynamically off current CTD DV01s, not a memorized ratio.
