Workbook

Sheet READ ME
A1: Intrinsic EV / NPV — DRAFT v2 (CORZ, WULF, CLSK)
A2: SOTP: Landlord (Morgan Stanley framework) + Mining (finite life) + BTC treasury − net debt − minorities.
A4: Landlord = real estate. Signed colocation @10% WACC, pipeline @11%, 85% NOI margin, signing 100% × COD 85% on signed deals.
A5: Disclosed $/MW (lease rev ÷ billable MW) values operating & signed capacity; generic $/MW (noted) only for un-leased/pipeline.
A6: Mining = 5-yr finite life, no perpetuity, scales with BTC scenario; loss-making mining floored at 0. Treasury marked at weighted price.
A7: Overhead = SG&A net of stock-comp, capitalized at 12%. Risk = WACC + discrete COD/lease-up probabilities + 3 BTC scenarios.
A9: Flagged for verification: WULF ~$5.2B gross debt and its SBC (10-K ~$20M vs Q1'26 cash-flow ~$101M); CORZ/CLSK SG&A are estimates.
A10: Market-cap cells blank — fill to see upside/downside (live pull declined).

Sheet CORRECTION LOG
A1: SOTP MODEL — CORRECTION LOG
A2: Generated 2026-06-27. Source: Q1'26 10-Q (CIFR) + earnings call.
A4: Cell | B4: Old Value | C4: New Value | D4: Source / Reason
A5: Assumptions!C10 | B5: $78,000 | C5: $100,688 | D5: BTC anchor: CIFR Q1'26 realized ($34,838K rev ÷ 346 BTC). Prior $78k was stale.
A6: CIFR!C7 | B6: 0 MW | C6: 493 MW | D6: Signed-not-energized: Barber Lake 207MW (Fluidstack) + Black Pearl 216MW (Amazon) + Stingray 70MW. Q1'26 10-Q project disclosures.
A7: CIFR!C10 | B7: 700 MW | C7: 207 MW | D7: Pipeline: signed leases moved to C7; ~207 MW remaining unsigned/dev capacity.
A8: CIFR!C12 | B8: $70,820K | C8: $72,000K | D8: Mining cost: Q1'26 10-Q CoR $18,000K/q × 4 = $72,000K/yr.
A9: CIFR!C13 | B9: 792 BTC | C9: 1,116 BTC | D9: BTC treasury: Q1'26 10-Q 'digital assets held 1,116 BTC at FV $111.5M'. Prior 792 was stale.
A11: STILL NEEDS VERIFICATION (EDGAR blocked — cannot pull directly):
A12: WULF!C15 | B12: $80,000K SBC | C12: UNVERIFIED | D12: FY25 10-K SG&A cites ~$20M vs Q1'26 cash-flow $101M. EDGAR access blocked — VERIFY.
A13: CORZ!C14 | B13: $150,000K SG&A | C13: ESTIMATE | D13: SG&A not confirmed from SEC filing. Mark ESTIMATE until verified.
A14: CLSK!C14 | B14: $120,000K SG&A | C14: ESTIMATE | D14: SG&A not confirmed from SEC filing.
A15: CLSK!C15 | B15: $70,000K SBC | C15: ESTIMATE | D15: SBC not confirmed from SEC filing.
A16: HUT!C7 | B16: 0 MW | C16: UNVERIFIED | D16: HUT signed AI DC leases ($16.8B TCV) → MW equivalent not confirmed from SEC filing. Needs 10-Q review.

Sheet Assumptions
B1: GLOBAL ASSUMPTIONS — drive every company tab
B2: BITCOIN & MINING
B3: BTC price — Bear ($) | C3: 45000 | D3: Scenario low
B4: BTC price — Base ($) | C4: 95000 | D4: INPUT — set to current spot / your base view
B5: BTC price — Bull ($) | C5: 150000 | D5: Scenario high
B6: Weight — Bear | C6: 0.25 | D6: Scenario probabilities (sum to 100%)
B7: Weight — Base | C7: 0.5
B8: Weight — Bull | C8: 0.25
B9: BTC price — probability-weighted ($) | C9: =C3*C6+C4*C7+C5*C8 | D9: Drives mining revenue & treasury mark
B10: BTC anchor price during reporting qtr ($) | C10: 100688 | D10: UPDATED: Q1'26 realized (CIFR $34,838K ÷ 346 BTC). Was $78,000.
B11: Annual difficulty / hashrate growth | C11: 0.15 | D11: Drags BTC volume over time
B12: Mining horizon (yrs, finite life) | C12: 5 | D12: No perpetuity — mining terminal value ~0
B13: Mining discount rate | C13: 0.2 | D13: High — commodity / obsolescence / halving
B14: Mining maintenance capex (% of gross profit) | C14: 0.25 | D14: Fleet replacement
B15: LANDLORD (Morgan Stanley framework)
B16: Signed colocation WACC | C16: 0.1 | D16: 9-12% by tenant credit & funding risk
B17: Pipeline WACC | C17: 0.11 | D17: Higher — unsigned / early-stage
B18: Hosting WACC | C18: 0.13 | D18: 3rd-party mining hosting
B19: Colocation NOI margin | C19: 0.85 | D19: Gross lease → NOI; triple-net can be higher
B20: Signed deal signing probability | C20: 1 | D20: Already signed
B21: Construction / COD probability (signed) | C21: 0.85 | D21: Execution risk on signed-but-unbuilt
B22: Pipeline COD probability (unsigned) | C22: 0.5 | D22: Execution risk on unsigned pipeline
B23: Un-leased powered-MW lease-up probability | C23: 0.6 | D23: Powered, no tenant yet
B24: Pipeline time-to-COD discount factor | C24: 0.7 | D24: Years until cash flows start
B25: HPC NOI $/MW/yr — generic ($000) | C25: 1100 | D25: Fallback for un-leased/pipeline (no disclosed rate)
B26: Hosting NOI $/MW/yr ($000) | C26: 350 | D26: If no disclosed hosting revenue
B27: HPC build capex $/MW ($000) | C27: 9000 | D27: Powered shell+cooling; tenant funds GPUs
B28: BRIDGE
B29: Corporate overhead cap rate | C29: 0.12 | D29: Capitalizes cash SG&A (net of stock-comp)

Sheet Summary
B1: SUMMARY — intrinsic vs market (fill market caps on each company tab)
B3: Ticker | C3: Company | D3: Intrinsic EV | E3: Intrinsic equity | F3: $/share | G3: EV/sec.MW | H3: Market cap | I3: Upside
B4: CORZ | C4: Core Scientific | D4: =CORZ!C42 | E4: =CORZ!C43 | F4: =CORZ!C44 | G4: =CORZ!C45 | H4: =CORZ!C48 | I4: =CORZ!C50
B5: APLD | C5: Applied Digital | D5: =APLD!C42 | E5: =APLD!C43 | F5: =APLD!C44 | G5: =APLD!C45 | H5: =APLD!C48 | I5: =APLD!C50
B6: WULF | C6: TeraWulf | D6: =WULF!C42 | E6: =WULF!C43 | F6: =WULF!C44 | G6: =WULF!C45 | H6: =WULF!C48 | I6: =WULF!C50
B7: RIOT | C7: Riot Platforms | D7: =RIOT!C42 | E7: =RIOT!C43 | F7: =RIOT!C44 | G7: =RIOT!C45 | H7: =RIOT!C48 | I7: =RIOT!C50
B8: HUT | C8: Hut 8 | D8: =HUT!C42 | E8: =HUT!C43 | F8: =HUT!C44 | G8: =HUT!C45 | H8: =HUT!C48 | I8: =HUT!C50
B9: CIFR | C9: Cipher Digital | D9: =CIFR!C42 | E9: =CIFR!C43 | F9: =CIFR!C44 | G9: =CIFR!C45 | H9: =CIFR!C48 | I9: =CIFR!C50
B10: CLSK | C10: CleanSpark | D10: =CLSK!C42 | E10: =CLSK!C43 | F10: =CLSK!C44 | G10: =CLSK!C45 | H10: =CLSK!C48 | I10: =CLSK!C50
B11: KEEL | C11: Keel (fka Bitfarms/Stronghold) | D11: =KEEL!C42 | E11: =KEEL!C43 | F11: =KEEL!C44 | G11: =KEEL!C45 | H11: =KEEL!C48 | I11: =KEEL!C50
B12: SLNH | C12: Soluna Holdings | D12: =SLNH!C42 | E12: =SLNH!C43 | F12: =SLNH!C44 | G12: =SLNH!C45 | H12: =SLNH!C48 | I12: =SLNH!C50
B13: GLXY | C13: Galaxy Digital | D13: =GLXY!C42 | E13: =GLXY!C43 | F13: =GLXY!C44 | G13: =GLXY!C45 | H13: =GLXY!C48 | I13: =GLXY!C50
C15: Note: GLXY equity is NOT meaningful here (financial-services value excluded). APLD/SLNH/HUT equity is minority-adjusted (NCI deducted). Fill yellow market-cap cells on each tab to populate upside.

Sheet CORZ
B1: CORZ — Core Scientific | Pure landlord (CoreWeave colocation)
B2: Yellow = input. Everything else is a formula. $000 unless noted.
B4: INPUTS (from filings — Source at bottom)
B5: Operating (billable) lease revenue, ann. ($000) | C5: 310156
B6: underlying billable MW (#) | C6: 225 | D6: → disclosed $/MW
B7: Signed-but-not-energized MW (#) | C7: 365 | D7: Signed leases, not yet built
B8: Un-leased powered MW (#) | C8: 685
B9: Hosting revenue, ann. ($000) | C9: 30400 | D9: 3rd-party miner hosting
B10: Pipeline MW in development (#) | C10: 585
B11: Mining revenue, annualized ($000) | C11: 120420
B12: Mining power/direct cost, ann. ($000) | C12: 188756
B13: BTC held in treasury (#) | C13: 0
B14: Corporate SG&A, annual ($000) | C14: 150000 | D14: ESTIMATE — verify
B15: of which stock-based comp ($000) | C15: 98236 | D15: Netted out of overhead
B16: Total debt ($000) | C16: 2085000
B17: Cash ($000) | C17: 1005148
B18: Noncontrolling interest ($000) | C18: 0
B19: Diluted shares (M) | C19: 317.9
B20: Total secured power (MW) | C20: 1860
B21: Disclosed $/MW (gross, computed) | C21: =IF(C6>0,C5/C6,Assumptions!$C$25) | D21: Used for operating & signed MW
B23: LANDLORD / REAL-ESTATE MODULE
B24: Operating leases: NOI ÷ signed WACC | C24: =(C5*Assumptions!$C$19)/Assumptions!$C$16
B25: Signed-not-energized (×signing ×COD) | C25: =C7*C21*Assumptions!$C$19*Assumptions!$C$20*Assumptions!$C$21/Assumptions!$C$16
B26: Un-leased powered MW (generic $/MW ×lease-up) | C26: =C8*Assumptions!$C$25*Assumptions!$C$19*Assumptions!$C$23/Assumptions!$C$17 | D26: Generic rate — no signed lease
B27: Hosting (NOI ÷ hosting WACC) | C27: =IF(C9>0,C9*Assumptions!$C$19/Assumptions!$C$18,0)
B28: Pipeline (dev value net of capex, risk-wtd) | C28: =MAX(0,(Assumptions!$C$25*Assumptions!$C$19/Assumptions!$C$17)-Assumptions!$C$27)*C10*Assumptions!$C$22*Assumptions!$C$24 | D28: Generic rate
B29: Landlord value (subtotal) | C29: =SUM(C24:C28)
B31: MINING MODULE (finite life; scales with BTC scenario)
B32: Year | C32: 1 | D32: 2 | E32: 3 | F32: 4 | G32: 5
B33: Mining revenue (scenario) | C33: =C11*(Assumptions!$C$9/Assumptions!$C$10)/((1+Assumptions!$C$11)^0) | D33: =C11*(Assumptions!$C$9/Assumptions!$C$10)/((1+Assumptions!$C$11)^1) | E33: =C11*(Assumptions!$C$9/Assumptions!$C$10)/((1+Assumptions!$C$11)^2) | F33: =C11*(Assumptions!$C$9/Assumptions!$C$10)/((1+Assumptions!$C$11)^3) | G33: =C11*(Assumptions!$C$9/Assumptions!$C$10)/((1+Assumptions!$C$11)^4)
B34: Less: power/direct cost | C34: =-C12 | D34: =-C12 | E34: =-C12 | F34: =-C12 | G34: =-C12
B35: FCF (after maint capex) | C35: =IF((C33+C34)>0,(C33+C34)*(1-Assumptions!$C$14),(C33+C34)) | D35: =IF((D33+D34)>0,(D33+D34)*(1-Assumptions!$C$14),(D33+D34)) | E35: =IF((E33+E34)>0,(E33+E34)*(1-Assumptions!$C$14),(E33+E34)) | F35: =IF((F33+F34)>0,(F33+F34)*(1-Assumptions!$C$14),(F33+F34)) | G35: =IF((G33+G34)>0,(G33+G34)*(1-Assumptions!$C$14),(G33+G34))
B36: PV of FCF | C36: =C35/((1+Assumptions!$C$13)^1) | D36: =D35/((1+Assumptions!$C$13)^2) | E36: =E35/((1+Assumptions!$C$13)^3) | F36: =F35/((1+Assumptions!$C$13)^4) | G36: =G35/((1+Assumptions!$C$13)^5)
B37: Mining value (Σ PV, floored at 0) | C37: =MAX(0,SUM(C36:G36))
B39: BTC TREASURY & BRIDGE
B40: BTC treasury (×weighted price) | C40: =C13*Assumptions!$C$9/1000
B41: Less: overhead, cash SG&A capitalized | C41: =-(C14-C15)/Assumptions!$C$29 | D41: SG&A net of stock-comp
B42: INTRINSIC ENTERPRISE VALUE (operating) | C42: =C29+C37+C41
C43: =C42+C40+C17-C16-C18
B44: Intrinsic value / share ($) | C44: =C43*1000/(C19*1000000)
...

Sheet APLD
B1: APLD — Applied Digital | Hosting + HPC landlord (CoreWeave); no self-mining
B2: Yellow = input. Everything else is a formula. $000 unless noted.
B4: INPUTS (from filings — Source at bottom)
B5: Operating (billable) lease revenue, ann. ($000) | C5: 0
B6: underlying billable MW (#) | C6: 0 | D6: → disclosed $/MW
B7: Signed-but-not-energized MW (#) | C7: 450 | D7: Signed leases, not yet built
B8: Un-leased powered MW (#) | C8: 0
B9: Hosting revenue, ann. ($000) | C9: 150000 | D9: 3rd-party miner hosting
B10: Pipeline MW in development (#) | C10: 200
B11: Mining revenue, annualized ($000) | C11: 0
B12: Mining power/direct cost, ann. ($000) | C12: 0
B13: BTC held in treasury (#) | C13: 0
B14: Corporate SG&A, annual ($000) | C14: 318892 | D14: FY25 10-K
B15: of which stock-based comp ($000) | C15: 40932 | D15: Netted out of overhead
B16: Total debt ($000) | C16: 2666154
B17: Cash ($000) | C17: 1730440
B18: Noncontrolling interest ($000) | C18: 923065
B19: Diluted shares (M) | C19: 285.8
B20: Total secured power (MW) | C20: 900
B21: Disclosed $/MW (gross, computed) | C21: =IF(C6>0,C5/C6,Assumptions!$C$25) | D21: Used for operating & signed MW
B23: LANDLORD / REAL-ESTATE MODULE
B24: Operating leases: NOI ÷ signed WACC | C24: =(C5*Assumptions!$C$19)/Assumptions!$C$16
B25: Signed-not-energized (×signing ×COD) | C25: =C7*C21*Assumptions!$C$19*Assumptions!$C$20*Assumptions!$C$21/Assumptions!$C$16
B26: Un-leased powered MW (generic $/MW ×lease-up) | C26: =C8*Assumptions!$C$25*Assumptions!$C$19*Assumptions!$C$23/Assumptions!$C$17 | D26: Generic rate — no signed lease
B27: Hosting (NOI ÷ hosting WACC) | C27: =IF(C9>0,C9*Assumptions!$C$19/Assumptions!$C$18,0)
B28: Pipeline (dev value net of capex, risk-wtd) | C28: =MAX(0,(Assumptions!$C$25*Assumptions!$C$19/Assumptions!$C$17)-Assumptions!$C$27)*C10*Assumptions!$C$22*Assumptions!$C$24 | D28: Generic rate
B29: Landlord value (subtotal) | C29: =SUM(C24:C28)
B31: MINING MODULE (finite life; scales with BTC scenario)
B32: Year | C32: 1 | D32: 2 | E32: 3 | F32: 4 | G32: 5
B33: Mining revenue (scenario) | C33: =C11*(Assumptions!$C$9/Assumptions!$C$10)/((1+Assumptions!$C$11)^0) | D33: =C11*(Assumptions!$C$9/Assumptions!$C$10)/((1+Assumptions!$C$11)^1) | E33: =C11*(Assumptions!$C$9/Assumptions!$C$10)/((1+Assumptions!$C$11)^2) | F33: =C11*(Assumptions!$C$9/Assumptions!$C$10)/((1+Assumptions!$C$11)^3) | G33: =C11*(Assumptions!$C$9/Assumptions!$C$10)/((1+Assumptions!$C$11)^4)
B34: Less: power/direct cost | C34: =-C12 | D34: =-C12 | E34: =-C12 | F34: =-C12 | G34: =-C12
B35: FCF (after maint capex) | C35: =IF((C33+C34)>0,(C33+C34)*(1-Assumptions!$C$14),(C33+C34)) | D35: =IF((D33+D34)>0,(D33+D34)*(1-Assumptions!$C$14),(D33+D34)) | E35: =IF((E33+E34)>0,(E33+E34)*(1-Assumptions!$C$14),(E33+E34)) | F35: =IF((F33+F34)>0,(F33+F34)*(1-Assumptions!$C$14),(F33+F34)) | G35: =IF((G33+G34)>0,(G33+G34)*(1-Assumptions!$C$14),(G33+G34))
B36: PV of FCF | C36: =C35/((1+Assumptions!$C$13)^1) | D36: =D35/((1+Assumptions!$C$13)^2) | E36: =E35/((1+Assumptions!$C$13)^3) | F36: =F35/((1+Assumptions!$C$13)^4) | G36: =G35/((1+Assumptions!$C$13)^5)
B37: Mining value (Σ PV, floored at 0) | C37: =MAX(0,SUM(C36:G36))
B39: BTC TREASURY & BRIDGE
B40: BTC treasury (×weighted price) | C40: =C13*Assumptions!$C$9/1000
B41: Less: overhead, cash SG&A capitalized | C41: =-(C14-C15)/Assumptions!$C$29 | D41: SG&A net of stock-comp
B42: INTRINSIC ENTERPRISE VALUE (operating) | C42: =C29+C37+C41
C43: =C42+C40+C17-C16-C18
B44: Intrinsic value / share ($) | C44: =C43*1000/(C19*1000000)
...

Sheet WULF
B1: WULF — TeraWulf | Hybrid (mining + signed HPC)
B2: Yellow = input. Everything else is a formula. $000 unless noted.
B4: INPUTS (from filings — Source at bottom)
B5: Operating (billable) lease revenue, ann. ($000) | C5: 84088
B6: underlying billable MW (#) | C6: 60 | D6: → disclosed $/MW
B7: Signed-but-not-energized MW (#) | C7: 260 | D7: Signed leases, not yet built
B8: Un-leased powered MW (#) | C8: 0
B9: Hosting revenue, ann. ($000) | C9: 0 | D9: 3rd-party miner hosting
B10: Pipeline MW in development (#) | C10: 168
B11: Mining revenue, annualized ($000) | C11: 51960
B12: Mining power/direct cost, ann. ($000) | C12: 31000
B13: BTC held in treasury (#) | C13: 18
B14: Corporate SG&A, annual ($000) | C14: 147800 | D14: FY25 10-K
B15: of which stock-based comp ($000) | C15: 80000 | D15: Netted out of overhead
B16: Total debt ($000) | C16: 5191378
B17: Cash ($000) | C17: 2629995
B18: Noncontrolling interest ($000) | C18: 1154
B19: Diluted shares (M) | C19: 495.5
B20: Total secured power (MW) | C20: 525
B21: Disclosed $/MW (gross, computed) | C21: =IF(C6>0,C5/C6,Assumptions!$C$25) | D21: Used for operating & signed MW
B23: LANDLORD / REAL-ESTATE MODULE
B24: Operating leases: NOI ÷ signed WACC | C24: =(C5*Assumptions!$C$19)/Assumptions!$C$16
B25: Signed-not-energized (×signing ×COD) | C25: =C7*C21*Assumptions!$C$19*Assumptions!$C$20*Assumptions!$C$21/Assumptions!$C$16
B26: Un-leased powered MW (generic $/MW ×lease-up) | C26: =C8*Assumptions!$C$25*Assumptions!$C$19*Assumptions!$C$23/Assumptions!$C$17 | D26: Generic rate — no signed lease
B27: Hosting (NOI ÷ hosting WACC) | C27: =IF(C9>0,C9*Assumptions!$C$19/Assumptions!$C$18,0)
B28: Pipeline (dev value net of capex, risk-wtd) | C28: =MAX(0,(Assumptions!$C$25*Assumptions!$C$19/Assumptions!$C$17)-Assumptions!$C$27)*C10*Assumptions!$C$22*Assumptions!$C$24 | D28: Generic rate
B29: Landlord value (subtotal) | C29: =SUM(C24:C28)
B31: MINING MODULE (finite life; scales with BTC scenario)
B32: Year | C32: 1 | D32: 2 | E32: 3 | F32: 4 | G32: 5
B33: Mining revenue (scenario) | C33: =C11*(Assumptions!$C$9/Assumptions!$C$10)/((1+Assumptions!$C$11)^0) | D33: =C11*(Assumptions!$C$9/Assumptions!$C$10)/((1+Assumptions!$C$11)^1) | E33: =C11*(Assumptions!$C$9/Assumptions!$C$10)/((1+Assumptions!$C$11)^2) | F33: =C11*(Assumptions!$C$9/Assumptions!$C$10)/((1+Assumptions!$C$11)^3) | G33: =C11*(Assumptions!$C$9/Assumptions!$C$10)/((1+Assumptions!$C$11)^4)
B34: Less: power/direct cost | C34: =-C12 | D34: =-C12 | E34: =-C12 | F34: =-C12 | G34: =-C12
B35: FCF (after maint capex) | C35: =IF((C33+C34)>0,(C33+C34)*(1-Assumptions!$C$14),(C33+C34)) | D35: =IF((D33+D34)>0,(D33+D34)*(1-Assumptions!$C$14),(D33+D34)) | E35: =IF((E33+E34)>0,(E33+E34)*(1-Assumptions!$C$14),(E33+E34)) | F35: =IF((F33+F34)>0,(F33+F34)*(1-Assumptions!$C$14),(F33+F34)) | G35: =IF((G33+G34)>0,(G33+G34)*(1-Assumptions!$C$14),(G33+G34))
B36: PV of FCF | C36: =C35/((1+Assumptions!$C$13)^1) | D36: =D35/((1+Assumptions!$C$13)^2) | E36: =E35/((1+Assumptions!$C$13)^3) | F36: =F35/((1+Assumptions!$C$13)^4) | G36: =G35/((1+Assumptions!$C$13)^5)
B37: Mining value (Σ PV, floored at 0) | C37: =MAX(0,SUM(C36:G36))
B39: BTC TREASURY & BRIDGE
B40: BTC treasury (×weighted price) | C40: =C13*Assumptions!$C$9/1000
B41: Less: overhead, cash SG&A capitalized | C41: =-(C14-C15)/Assumptions!$C$29 | D41: SG&A net of stock-comp
B42: INTRINSIC ENTERPRISE VALUE (operating) | C42: =C29+C37+C41
C43: =C42+C40+C17-C16-C18
B44: Intrinsic value / share ($) | C44: =C43*1000/(C19*1000000)
...

Sheet RIOT
B1: RIOT — Riot Platforms | Miner + ramping HPC (AMD) + engineering
B2: Yellow = input. Everything else is a formula. $000 unless noted.
B4: INPUTS (from filings — Source at bottom)
B5: Operating (billable) lease revenue, ann. ($000) | C5: 132600
B6: underlying billable MW (#) | C6: 100 | D6: → disclosed $/MW
B7: Signed-but-not-energized MW (#) | C7: 100 | D7: Signed leases, not yet built
B8: Un-leased powered MW (#) | C8: 0
B9: Hosting revenue, ann. ($000) | C9: 0 | D9: 3rd-party miner hosting
B10: Pipeline MW in development (#) | C10: 400
B11: Mining revenue, annualized ($000) | C11: 447580
B12: Mining power/direct cost, ann. ($000) | C12: 347048
B13: BTC held in treasury (#) | C13: 15679
B14: Corporate SG&A, annual ($000) | C14: 304720 | D14: FY25 10-K
B15: of which stock-based comp ($000) | C15: 156664 | D15: Netted out of overhead
B16: Total debt ($000) | C16: 850000
B17: Cash ($000) | C17: 205666
B18: Noncontrolling interest ($000) | C18: 0
B19: Diluted shares (M) | C19: 378.2
B20: Total secured power (MW) | C20: 1262
B21: Disclosed $/MW (gross, computed) | C21: =IF(C6>0,C5/C6,Assumptions!$C$25) | D21: Used for operating & signed MW
B23: LANDLORD / REAL-ESTATE MODULE
B24: Operating leases: NOI ÷ signed WACC | C24: =(C5*Assumptions!$C$19)/Assumptions!$C$16
B25: Signed-not-energized (×signing ×COD) | C25: =C7*C21*Assumptions!$C$19*Assumptions!$C$20*Assumptions!$C$21/Assumptions!$C$16
B26: Un-leased powered MW (generic $/MW ×lease-up) | C26: =C8*Assumptions!$C$25*Assumptions!$C$19*Assumptions!$C$23/Assumptions!$C$17 | D26: Generic rate — no signed lease
B27: Hosting (NOI ÷ hosting WACC) | C27: =IF(C9>0,C9*Assumptions!$C$19/Assumptions!$C$18,0)
B28: Pipeline (dev value net of capex, risk-wtd) | C28: =MAX(0,(Assumptions!$C$25*Assumptions!$C$19/Assumptions!$C$17)-Assumptions!$C$27)*C10*Assumptions!$C$22*Assumptions!$C$24 | D28: Generic rate
B29: Landlord value (subtotal) | C29: =SUM(C24:C28)
B31: MINING MODULE (finite life; scales with BTC scenario)
B32: Year | C32: 1 | D32: 2 | E32: 3 | F32: 4 | G32: 5
B33: Mining revenue (scenario) | C33: =C11*(Assumptions!$C$9/Assumptions!$C$10)/((1+Assumptions!$C$11)^0) | D33: =C11*(Assumptions!$C$9/Assumptions!$C$10)/((1+Assumptions!$C$11)^1) | E33: =C11*(Assumptions!$C$9/Assumptions!$C$10)/((1+Assumptions!$C$11)^2) | F33: =C11*(Assumptions!$C$9/Assumptions!$C$10)/((1+Assumptions!$C$11)^3) | G33: =C11*(Assumptions!$C$9/Assumptions!$C$10)/((1+Assumptions!$C$11)^4)
B34: Less: power/direct cost | C34: =-C12 | D34: =-C12 | E34: =-C12 | F34: =-C12 | G34: =-C12
B35: FCF (after maint capex) | C35: =IF((C33+C34)>0,(C33+C34)*(1-Assumptions!$C$14),(C33+C34)) | D35: =IF((D33+D34)>0,(D33+D34)*(1-Assumptions!$C$14),(D33+D34)) | E35: =IF((E33+E34)>0,(E33+E34)*(1-Assumptions!$C$14),(E33+E34)) | F35: =IF((F33+F34)>0,(F33+F34)*(1-Assumptions!$C$14),(F33+F34)) | G35: =IF((G33+G34)>0,(G33+G34)*(1-Assumptions!$C$14),(G33+G34))
B36: PV of FCF | C36: =C35/((1+Assumptions!$C$13)^1) | D36: =D35/((1+Assumptions!$C$13)^2) | E36: =E35/((1+Assumptions!$C$13)^3) | F36: =F35/((1+Assumptions!$C$13)^4) | G36: =G35/((1+Assumptions!$C$13)^5)
B37: Mining value (Σ PV, floored at 0) | C37: =MAX(0,SUM(C36:G36))
B39: BTC TREASURY & BRIDGE
B40: BTC treasury (×weighted price) | C40: =C13*Assumptions!$C$9/1000
B41: Less: overhead, cash SG&A capitalized | C41: =-(C14-C15)/Assumptions!$C$29 | D41: SG&A net of stock-comp
B42: INTRINSIC ENTERPRISE VALUE (operating) | C42: =C29+C37+C41
C43: =C42+C40+C17-C16-C18
B44: Intrinsic value / share ($) | C44: =C43*1000/(C19*1000000)
...

Sheet HUT
B1: HUT — Hut 8 | Miner via American Bitcoin (minority) + power/infra
B2: Yellow = input. Everything else is a formula. $000 unless noted.
B4: INPUTS (from filings — Source at bottom)
B5: Operating (billable) lease revenue, ann. ($000) | C5: 0
B6: underlying billable MW (#) | C6: 0 | D6: → disclosed $/MW
B7: Signed-but-not-energized MW (#) | C7: 0 | D7: Signed leases, not yet built
B8: Un-leased powered MW (#) | C8: 0
B9: Hosting revenue, ann. ($000) | C9: 5212 | D9: 3rd-party miner hosting
B10: Pipeline MW in development (#) | C10: 330
B11: Mining revenue, annualized ($000) | C11: 263896
B12: Mining power/direct cost, ann. ($000) | C12: 158338
B13: BTC held in treasury (#) | C13: 16331
B14: Corporate SG&A, annual ($000) | C14: 326960 | D14: FY25 10-K
B15: of which stock-based comp ($000) | C15: 203496 | D15: Netted out of overhead
B16: Total debt ($000) | C16: 422911
B17: Cash ($000) | C17: 250000
B18: Noncontrolling interest ($000) | C18: 310337
B19: Diluted shares (M) | C19: 112.6
B20: Total secured power (MW) | C20: 400
B21: Disclosed $/MW (gross, computed) | C21: =IF(C6>0,C5/C6,Assumptions!$C$25) | D21: Used for operating & signed MW
B23: LANDLORD / REAL-ESTATE MODULE
B24: Operating leases: NOI ÷ signed WACC | C24: =(C5*Assumptions!$C$19)/Assumptions!$C$16
B25: Signed-not-energized (×signing ×COD) | C25: =C7*C21*Assumptions!$C$19*Assumptions!$C$20*Assumptions!$C$21/Assumptions!$C$16
B26: Un-leased powered MW (generic $/MW ×lease-up) | C26: =C8*Assumptions!$C$25*Assumptions!$C$19*Assumptions!$C$23/Assumptions!$C$17 | D26: Generic rate — no signed lease
B27: Hosting (NOI ÷ hosting WACC) | C27: =IF(C9>0,C9*Assumptions!$C$19/Assumptions!$C$18,0)
B28: Pipeline (dev value net of capex, risk-wtd) | C28: =MAX(0,(Assumptions!$C$25*Assumptions!$C$19/Assumptions!$C$17)-Assumptions!$C$27)*C10*Assumptions!$C$22*Assumptions!$C$24 | D28: Generic rate
B29: Landlord value (subtotal) | C29: =SUM(C24:C28)
B31: MINING MODULE (finite life; scales with BTC scenario)
B32: Year | C32: 1 | D32: 2 | E32: 3 | F32: 4 | G32: 5
B33: Mining revenue (scenario) | C33: =C11*(Assumptions!$C$9/Assumptions!$C$10)/((1+Assumptions!$C$11)^0) | D33: =C11*(Assumptions!$C$9/Assumptions!$C$10)/((1+Assumptions!$C$11)^1) | E33: =C11*(Assumptions!$C$9/Assumptions!$C$10)/((1+Assumptions!$C$11)^2) | F33: =C11*(Assumptions!$C$9/Assumptions!$C$10)/((1+Assumptions!$C$11)^3) | G33: =C11*(Assumptions!$C$9/Assumptions!$C$10)/((1+Assumptions!$C$11)^4)
B34: Less: power/direct cost | C34: =-C12 | D34: =-C12 | E34: =-C12 | F34: =-C12 | G34: =-C12
B35: FCF (after maint capex) | C35: =IF((C33+C34)>0,(C33+C34)*(1-Assumptions!$C$14),(C33+C34)) | D35: =IF((D33+D34)>0,(D33+D34)*(1-Assumptions!$C$14),(D33+D34)) | E35: =IF((E33+E34)>0,(E33+E34)*(1-Assumptions!$C$14),(E33+E34)) | F35: =IF((F33+F34)>0,(F33+F34)*(1-Assumptions!$C$14),(F33+F34)) | G35: =IF((G33+G34)>0,(G33+G34)*(1-Assumptions!$C$14),(G33+G34))
B36: PV of FCF | C36: =C35/((1+Assumptions!$C$13)^1) | D36: =D35/((1+Assumptions!$C$13)^2) | E36: =E35/((1+Assumptions!$C$13)^3) | F36: =F35/((1+Assumptions!$C$13)^4) | G36: =G35/((1+Assumptions!$C$13)^5)
B37: Mining value (Σ PV, floored at 0) | C37: =MAX(0,SUM(C36:G36))
B39: BTC TREASURY & BRIDGE
B40: BTC treasury (×weighted price) | C40: =C13*Assumptions!$C$9/1000
B41: Less: overhead, cash SG&A capitalized | C41: =-(C14-C15)/Assumptions!$C$29 | D41: SG&A net of stock-comp
B42: INTRINSIC ENTERPRISE VALUE (operating) | C42: =C29+C37+C41
C43: =C42+C40+C17-C16-C18
B44: Intrinsic value / share ($) | C44: =C43*1000/(C19*1000000)
...

Sheet CIFR
B1: CIFR — Cipher Digital | Miner today → future HPC landlord
B2: Yellow = input. Everything else is a formula. $000 unless noted.
B4: INPUTS (from filings — Source at bottom)
B5: Operating (billable) lease revenue, ann. ($000) | C5: 0
B6: underlying billable MW (#) | C6: 0 | D6: → disclosed $/MW
B7: Signed-but-not-energized MW (#) | C7: 493 | D7: UPDATED: 493 MW signed (Barber Lake 207 + Black Pearl 216 + Stingray 70). Q1'26 10-Q.
B8: Un-leased powered MW (#) | C8: 0
B9: Hosting revenue, ann. ($000) | C9: 0 | D9: 3rd-party miner hosting
B10: Pipeline MW in development (#) | C10: 207 | D10: UPDATED: ~207 MW unsigned pipeline (signed leases moved to C7). Was 700.
B11: Mining revenue, annualized ($000) | C11: 139352
B12: Mining power/direct cost, ann. ($000) | C12: 72000 | D12: UPDATED: Q1'26 10-Q CoR $18,000K/q×4. Was $70,820K.
B13: BTC held in treasury (#) | C13: 1116 | D13: UPDATED: Q1'26 10-Q: 1,116 BTC @FV $111.5M. Was 792.
B14: Corporate SG&A, annual ($000) | C14: 186976 | D14: FY25 10-K
B15: of which stock-based comp ($000) | C15: 108192 | D15: Netted out of overhead
B16: Total debt ($000) | C16: 1487078
B17: Cash ($000) | C17: 715203
B18: Noncontrolling interest ($000) | C18: 25679
B19: Diluted shares (M) | C19: 409
B20: Total secured power (MW) | C20: 1207
B21: Disclosed $/MW (gross, computed) | C21: =IF(C6>0,C5/C6,Assumptions!$C$25) | D21: Used for operating & signed MW
B23: LANDLORD / REAL-ESTATE MODULE
B24: Operating leases: NOI ÷ signed WACC | C24: =(C5*Assumptions!$C$19)/Assumptions!$C$16
B25: Signed-not-energized (×signing ×COD) | C25: =C7*C21*Assumptions!$C$19*Assumptions!$C$20*Assumptions!$C$21/Assumptions!$C$16
B26: Un-leased powered MW (generic $/MW ×lease-up) | C26: =C8*Assumptions!$C$25*Assumptions!$C$19*Assumptions!$C$23/Assumptions!$C$17 | D26: Generic rate — no signed lease
B27: Hosting (NOI ÷ hosting WACC) | C27: =IF(C9>0,C9*Assumptions!$C$19/Assumptions!$C$18,0)
B28: Pipeline (dev value net of capex, risk-wtd) | C28: =MAX(0,(Assumptions!$C$25*Assumptions!$C$19/Assumptions!$C$17)-Assumptions!$C$27)*C10*Assumptions!$C$22*Assumptions!$C$24 | D28: Generic rate
B29: Landlord value (subtotal) | C29: =SUM(C24:C28)
B31: MINING MODULE (finite life; scales with BTC scenario)
B32: Year | C32: 1 | D32: 2 | E32: 3 | F32: 4 | G32: 5
B33: Mining revenue (scenario) | C33: =C11*(Assumptions!$C$9/Assumptions!$C$10)/((1+Assumptions!$C$11)^0) | D33: =C11*(Assumptions!$C$9/Assumptions!$C$10)/((1+Assumptions!$C$11)^1) | E33: =C11*(Assumptions!$C$9/Assumptions!$C$10)/((1+Assumptions!$C$11)^2) | F33: =C11*(Assumptions!$C$9/Assumptions!$C$10)/((1+Assumptions!$C$11)^3) | G33: =C11*(Assumptions!$C$9/Assumptions!$C$10)/((1+Assumptions!$C$11)^4)
B34: Less: power/direct cost | C34: =-C12 | D34: =-C12 | E34: =-C12 | F34: =-C12 | G34: =-C12
B35: FCF (after maint capex) | C35: =IF((C33+C34)>0,(C33+C34)*(1-Assumptions!$C$14),(C33+C34)) | D35: =IF((D33+D34)>0,(D33+D34)*(1-Assumptions!$C$14),(D33+D34)) | E35: =IF((E33+E34)>0,(E33+E34)*(1-Assumptions!$C$14),(E33+E34)) | F35: =IF((F33+F34)>0,(F33+F34)*(1-Assumptions!$C$14),(F33+F34)) | G35: =IF((G33+G34)>0,(G33+G34)*(1-Assumptions!$C$14),(G33+G34))
B36: PV of FCF | C36: =C35/((1+Assumptions!$C$13)^1) | D36: =D35/((1+Assumptions!$C$13)^2) | E36: =E35/((1+Assumptions!$C$13)^3) | F36: =F35/((1+Assumptions!$C$13)^4) | G36: =G35/((1+Assumptions!$C$13)^5)
B37: Mining value (Σ PV, floored at 0) | C37: =MAX(0,SUM(C36:G36))
B39: BTC TREASURY & BRIDGE
B40: BTC treasury (×weighted price) | C40: =C13*Assumptions!$C$9/1000
B41: Less: overhead, cash SG&A capitalized | C41: =-(C14-C15)/Assumptions!$C$29 | D41: SG&A net of stock-comp
B42: INTRINSIC ENTERPRISE VALUE (operating) | C42: =C29+C37+C41
C43: =C42+C40+C17-C16-C18
B44: Intrinsic value / share ($) | C44: =C43*1000/(C19*1000000)
...

Sheet CLSK
B1: CLSK — CleanSpark | Near-pure miner + BTC treasury
B2: Yellow = input. Everything else is a formula. $000 unless noted.
B4: INPUTS (from filings — Source at bottom)
B5: Operating (billable) lease revenue, ann. ($000) | C5: 0
B6: underlying billable MW (#) | C6: 0 | D6: → disclosed $/MW
B7: Signed-but-not-energized MW (#) | C7: 0 | D7: Signed leases, not yet built
B8: Un-leased powered MW (#) | C8: 0
B9: Hosting revenue, ann. ($000) | C9: 0 | D9: 3rd-party miner hosting
B10: Pipeline MW in development (#) | C10: 300
B11: Mining revenue, annualized ($000) | C11: 545632
B12: Mining power/direct cost, ann. ($000) | C12: 308615
B13: BTC held in treasury (#) | C13: 11920
B14: Corporate SG&A, annual ($000) | C14: 120000 | D14: ESTIMATE — verify
B15: of which stock-based comp ($000) | C15: 70000 | D15: Netted out of overhead
B16: Total debt ($000) | C16: 1788196
B17: Cash ($000) | C17: 260287
B18: Noncontrolling interest ($000) | C18: 0
B19: Diluted shares (M) | C19: 256.6
B20: Total secured power (MW) | C20: 1809
B21: Disclosed $/MW (gross, computed) | C21: =IF(C6>0,C5/C6,Assumptions!$C$25) | D21: Used for operating & signed MW
B23: LANDLORD / REAL-ESTATE MODULE
B24: Operating leases: NOI ÷ signed WACC | C24: =(C5*Assumptions!$C$19)/Assumptions!$C$16
B25: Signed-not-energized (×signing ×COD) | C25: =C7*C21*Assumptions!$C$19*Assumptions!$C$20*Assumptions!$C$21/Assumptions!$C$16
B26: Un-leased powered MW (generic $/MW ×lease-up) | C26: =C8*Assumptions!$C$25*Assumptions!$C$19*Assumptions!$C$23/Assumptions!$C$17 | D26: Generic rate — no signed lease
B27: Hosting (NOI ÷ hosting WACC) | C27: =IF(C9>0,C9*Assumptions!$C$19/Assumptions!$C$18,0)
B28: Pipeline (dev value net of capex, risk-wtd) | C28: =MAX(0,(Assumptions!$C$25*Assumptions!$C$19/Assumptions!$C$17)-Assumptions!$C$27)*C10*Assumptions!$C$22*Assumptions!$C$24 | D28: Generic rate
B29: Landlord value (subtotal) | C29: =SUM(C24:C28)
B31: MINING MODULE (finite life; scales with BTC scenario)
B32: Year | C32: 1 | D32: 2 | E32: 3 | F32: 4 | G32: 5
B33: Mining revenue (scenario) | C33: =C11*(Assumptions!$C$9/Assumptions!$C$10)/((1+Assumptions!$C$11)^0) | D33: =C11*(Assumptions!$C$9/Assumptions!$C$10)/((1+Assumptions!$C$11)^1) | E33: =C11*(Assumptions!$C$9/Assumptions!$C$10)/((1+Assumptions!$C$11)^2) | F33: =C11*(Assumptions!$C$9/Assumptions!$C$10)/((1+Assumptions!$C$11)^3) | G33: =C11*(Assumptions!$C$9/Assumptions!$C$10)/((1+Assumptions!$C$11)^4)
B34: Less: power/direct cost | C34: =-C12 | D34: =-C12 | E34: =-C12 | F34: =-C12 | G34: =-C12
B35: FCF (after maint capex) | C35: =IF((C33+C34)>0,(C33+C34)*(1-Assumptions!$C$14),(C33+C34)) | D35: =IF((D33+D34)>0,(D33+D34)*(1-Assumptions!$C$14),(D33+D34)) | E35: =IF((E33+E34)>0,(E33+E34)*(1-Assumptions!$C$14),(E33+E34)) | F35: =IF((F33+F34)>0,(F33+F34)*(1-Assumptions!$C$14),(F33+F34)) | G35: =IF((G33+G34)>0,(G33+G34)*(1-Assumptions!$C$14),(G33+G34))
B36: PV of FCF | C36: =C35/((1+Assumptions!$C$13)^1) | D36: =D35/((1+Assumptions!$C$13)^2) | E36: =E35/((1+Assumptions!$C$13)^3) | F36: =F35/((1+Assumptions!$C$13)^4) | G36: =G35/((1+Assumptions!$C$13)^5)
B37: Mining value (Σ PV, floored at 0) | C37: =MAX(0,SUM(C36:G36))
B39: BTC TREASURY & BRIDGE
B40: BTC treasury (×weighted price) | C40: =C13*Assumptions!$C$9/1000
B41: Less: overhead, cash SG&A capitalized | C41: =-(C14-C15)/Assumptions!$C$29 | D41: SG&A net of stock-comp
B42: INTRINSIC ENTERPRISE VALUE (operating) | C42: =C29+C37+C41
C43: =C42+C40+C17-C16-C18
B44: Intrinsic value / share ($) | C44: =C43*1000/(C19*1000000)
...

Sheet KEEL
B1: KEEL — Keel (fka Bitfarms/Stronghold) | Pure miner (high-cost)
B2: Yellow = input. Everything else is a formula. $000 unless noted.
B4: INPUTS (from filings — Source at bottom)
B5: Operating (billable) lease revenue, ann. ($000) | C5: 0
B6: underlying billable MW (#) | C6: 0 | D6: → disclosed $/MW
B7: Signed-but-not-energized MW (#) | C7: 0 | D7: Signed leases, not yet built
B8: Un-leased powered MW (#) | C8: 0
B9: Hosting revenue, ann. ($000) | C9: 2764 | D9: 3rd-party miner hosting
B10: Pipeline MW in development (#) | C10: 18
B11: Mining revenue, annualized ($000) | C11: 119572
B12: Mining power/direct cost, ann. ($000) | C12: 71743
B13: BTC held in treasury (#) | C13: 0
B14: Corporate SG&A, annual ($000) | C14: 107348 | D14: FY25 10-K
B15: of which stock-based comp ($000) | C15: 14656 | D15: Netted out of overhead
B16: Total debt ($000) | C16: 590445
B17: Cash ($000) | C17: 50000
B18: Noncontrolling interest ($000) | C18: 0
B19: Diluted shares (M) | C19: 603.8
B20: Total secured power (MW) | C20: 141
B21: Disclosed $/MW (gross, computed) | C21: =IF(C6>0,C5/C6,Assumptions!$C$25) | D21: Used for operating & signed MW
B23: LANDLORD / REAL-ESTATE MODULE
B24: Operating leases: NOI ÷ signed WACC | C24: =(C5*Assumptions!$C$19)/Assumptions!$C$16
B25: Signed-not-energized (×signing ×COD) | C25: =C7*C21*Assumptions!$C$19*Assumptions!$C$20*Assumptions!$C$21/Assumptions!$C$16
B26: Un-leased powered MW (generic $/MW ×lease-up) | C26: =C8*Assumptions!$C$25*Assumptions!$C$19*Assumptions!$C$23/Assumptions!$C$17 | D26: Generic rate — no signed lease
B27: Hosting (NOI ÷ hosting WACC) | C27: =IF(C9>0,C9*Assumptions!$C$19/Assumptions!$C$18,0)
B28: Pipeline (dev value net of capex, risk-wtd) | C28: =MAX(0,(Assumptions!$C$25*Assumptions!$C$19/Assumptions!$C$17)-Assumptions!$C$27)*C10*Assumptions!$C$22*Assumptions!$C$24 | D28: Generic rate
B29: Landlord value (subtotal) | C29: =SUM(C24:C28)
B31: MINING MODULE (finite life; scales with BTC scenario)
B32: Year | C32: 1 | D32: 2 | E32: 3 | F32: 4 | G32: 5
B33: Mining revenue (scenario) | C33: =C11*(Assumptions!$C$9/Assumptions!$C$10)/((1+Assumptions!$C$11)^0) | D33: =C11*(Assumptions!$C$9/Assumptions!$C$10)/((1+Assumptions!$C$11)^1) | E33: =C11*(Assumptions!$C$9/Assumptions!$C$10)/((1+Assumptions!$C$11)^2) | F33: =C11*(Assumptions!$C$9/Assumptions!$C$10)/((1+Assumptions!$C$11)^3) | G33: =C11*(Assumptions!$C$9/Assumptions!$C$10)/((1+Assumptions!$C$11)^4)
B34: Less: power/direct cost | C34: =-C12 | D34: =-C12 | E34: =-C12 | F34: =-C12 | G34: =-C12
B35: FCF (after maint capex) | C35: =IF((C33+C34)>0,(C33+C34)*(1-Assumptions!$C$14),(C33+C34)) | D35: =IF((D33+D34)>0,(D33+D34)*(1-Assumptions!$C$14),(D33+D34)) | E35: =IF((E33+E34)>0,(E33+E34)*(1-Assumptions!$C$14),(E33+E34)) | F35: =IF((F33+F34)>0,(F33+F34)*(1-Assumptions!$C$14),(F33+F34)) | G35: =IF((G33+G34)>0,(G33+G34)*(1-Assumptions!$C$14),(G33+G34))
B36: PV of FCF | C36: =C35/((1+Assumptions!$C$13)^1) | D36: =D35/((1+Assumptions!$C$13)^2) | E36: =E35/((1+Assumptions!$C$13)^3) | F36: =F35/((1+Assumptions!$C$13)^4) | G36: =G35/((1+Assumptions!$C$13)^5)
B37: Mining value (Σ PV, floored at 0) | C37: =MAX(0,SUM(C36:G36))
B39: BTC TREASURY & BRIDGE
B40: BTC treasury (×weighted price) | C40: =C13*Assumptions!$C$9/1000
B41: Less: overhead, cash SG&A capitalized | C41: =-(C14-C15)/Assumptions!$C$29 | D41: SG&A net of stock-comp
B42: INTRINSIC ENTERPRISE VALUE (operating) | C42: =C29+C37+C41
C43: =C42+C40+C17-C16-C18
B44: Intrinsic value / share ($) | C44: =C43*1000/(C19*1000000)
...

Sheet SLNH
B1: SLNH — Soluna Holdings | Renewable hosting + small mining (JV-heavy)
B2: Yellow = input. Everything else is a formula. $000 unless noted.
B4: INPUTS (from filings — Source at bottom)
B5: Operating (billable) lease revenue, ann. ($000) | C5: 0
B6: underlying billable MW (#) | C6: 0 | D6: → disclosed $/MW
B7: Signed-but-not-energized MW (#) | C7: 0 | D7: Signed leases, not yet built
B8: Un-leased powered MW (#) | C8: 0
B9: Hosting revenue, ann. ($000) | C9: 26752 | D9: 3rd-party miner hosting
B10: Pipeline MW in development (#) | C10: 40
B11: Mining revenue, annualized ($000) | C11: 8676
B12: Mining power/direct cost, ann. ($000) | C12: 10676
B13: BTC held in treasury (#) | C13: 0
B14: Corporate SG&A, annual ($000) | C14: 64560 | D14: FY25 10-K
B15: of which stock-based comp ($000) | C15: 40888 | D15: Netted out of overhead
B16: Total debt ($000) | C16: 25951
B17: Cash ($000) | C17: 68572
B18: Noncontrolling interest ($000) | C18: 65797
B19: Diluted shares (M) | C19: 157.7
B20: Total secured power (MW) | C20: 123
B21: Disclosed $/MW (gross, computed) | C21: =IF(C6>0,C5/C6,Assumptions!$C$25) | D21: Used for operating & signed MW
B23: LANDLORD / REAL-ESTATE MODULE
B24: Operating leases: NOI ÷ signed WACC | C24: =(C5*Assumptions!$C$19)/Assumptions!$C$16
B25: Signed-not-energized (×signing ×COD) | C25: =C7*C21*Assumptions!$C$19*Assumptions!$C$20*Assumptions!$C$21/Assumptions!$C$16
B26: Un-leased powered MW (generic $/MW ×lease-up) | C26: =C8*Assumptions!$C$25*Assumptions!$C$19*Assumptions!$C$23/Assumptions!$C$17 | D26: Generic rate — no signed lease
B27: Hosting (NOI ÷ hosting WACC) | C27: =IF(C9>0,C9*Assumptions!$C$19/Assumptions!$C$18,0)
B28: Pipeline (dev value net of capex, risk-wtd) | C28: =MAX(0,(Assumptions!$C$25*Assumptions!$C$19/Assumptions!$C$17)-Assumptions!$C$27)*C10*Assumptions!$C$22*Assumptions!$C$24 | D28: Generic rate
B29: Landlord value (subtotal) | C29: =SUM(C24:C28)
B31: MINING MODULE (finite life; scales with BTC scenario)
B32: Year | C32: 1 | D32: 2 | E32: 3 | F32: 4 | G32: 5
B33: Mining revenue (scenario) | C33: =C11*(Assumptions!$C$9/Assumptions!$C$10)/((1+Assumptions!$C$11)^0) | D33: =C11*(Assumptions!$C$9/Assumptions!$C$10)/((1+Assumptions!$C$11)^1) | E33: =C11*(Assumptions!$C$9/Assumptions!$C$10)/((1+Assumptions!$C$11)^2) | F33: =C11*(Assumptions!$C$9/Assumptions!$C$10)/((1+Assumptions!$C$11)^3) | G33: =C11*(Assumptions!$C$9/Assumptions!$C$10)/((1+Assumptions!$C$11)^4)
B34: Less: power/direct cost | C34: =-C12 | D34: =-C12 | E34: =-C12 | F34: =-C12 | G34: =-C12
B35: FCF (after maint capex) | C35: =IF((C33+C34)>0,(C33+C34)*(1-Assumptions!$C$14),(C33+C34)) | D35: =IF((D33+D34)>0,(D33+D34)*(1-Assumptions!$C$14),(D33+D34)) | E35: =IF((E33+E34)>0,(E33+E34)*(1-Assumptions!$C$14),(E33+E34)) | F35: =IF((F33+F34)>0,(F33+F34)*(1-Assumptions!$C$14),(F33+F34)) | G35: =IF((G33+G34)>0,(G33+G34)*(1-Assumptions!$C$14),(G33+G34))
B36: PV of FCF | C36: =C35/((1+Assumptions!$C$13)^1) | D36: =D35/((1+Assumptions!$C$13)^2) | E36: =E35/((1+Assumptions!$C$13)^3) | F36: =F35/((1+Assumptions!$C$13)^4) | G36: =G35/((1+Assumptions!$C$13)^5)
B37: Mining value (Σ PV, floored at 0) | C37: =MAX(0,SUM(C36:G36))
B39: BTC TREASURY & BRIDGE
B40: BTC treasury (×weighted price) | C40: =C13*Assumptions!$C$9/1000
B41: Less: overhead, cash SG&A capitalized | C41: =-(C14-C15)/Assumptions!$C$29 | D41: SG&A net of stock-comp
B42: INTRINSIC ENTERPRISE VALUE (operating) | C42: =C29+C37+C41
C43: =C42+C40+C17-C16-C18
B44: Intrinsic value / share ($) | C44: =C43*1000/(C19*1000000)
...

Sheet GLXY
B1: GLXY — Galaxy Digital | Financial-services firm — Helios HPC sliver only
B2: Yellow = input. Everything else is a formula. $000 unless noted.
B4: INPUTS (from filings — Source at bottom)
B5: Operating (billable) lease revenue, ann. ($000) | C5: 0
B6: underlying billable MW (#) | C6: 0 | D6: → disclosed $/MW
B7: Signed-but-not-energized MW (#) | C7: 0 | D7: Signed leases, not yet built
B8: Un-leased powered MW (#) | C8: 0
B9: Hosting revenue, ann. ($000) | C9: 0 | D9: 3rd-party miner hosting
B10: Pipeline MW in development (#) | C10: 400
B11: Mining revenue, annualized ($000) | C11: 2836
B12: Mining power/direct cost, ann. ($000) | C12: 2800
B13: BTC held in treasury (#) | C13: 0
B14: Corporate SG&A, annual ($000) | C14: 81684 | D14: ESTIMATE — verify
B15: of which stock-based comp ($000) | C15: 20000 | D15: Netted out of overhead
B16: Total debt ($000) | C16: 3058426
B17: Cash ($000) | C17: 910691
B18: Noncontrolling interest ($000) | C18: 1079042
B19: Diluted shares (M) | C19: 389.9
B20: Total secured power (MW) | C20: 400
B21: Disclosed $/MW (gross, computed) | C21: =IF(C6>0,C5/C6,Assumptions!$C$25) | D21: Used for operating & signed MW
B23: LANDLORD / REAL-ESTATE MODULE
B24: Operating leases: NOI ÷ signed WACC | C24: =(C5*Assumptions!$C$19)/Assumptions!$C$16
B25: Signed-not-energized (×signing ×COD) | C25: =C7*C21*Assumptions!$C$19*Assumptions!$C$20*Assumptions!$C$21/Assumptions!$C$16
B26: Un-leased powered MW (generic $/MW ×lease-up) | C26: =C8*Assumptions!$C$25*Assumptions!$C$19*Assumptions!$C$23/Assumptions!$C$17 | D26: Generic rate — no signed lease
B27: Hosting (NOI ÷ hosting WACC) | C27: =IF(C9>0,C9*Assumptions!$C$19/Assumptions!$C$18,0)
B28: Pipeline (dev value net of capex, risk-wtd) | C28: =MAX(0,(Assumptions!$C$25*Assumptions!$C$19/Assumptions!$C$17)-Assumptions!$C$27)*C10*Assumptions!$C$22*Assumptions!$C$24 | D28: Generic rate
B29: Landlord value (subtotal) | C29: =SUM(C24:C28)
B31: MINING MODULE (finite life; scales with BTC scenario)
B32: Year | C32: 1 | D32: 2 | E32: 3 | F32: 4 | G32: 5
B33: Mining revenue (scenario) | C33: =C11*(Assumptions!$C$9/Assumptions!$C$10)/((1+Assumptions!$C$11)^0) | D33: =C11*(Assumptions!$C$9/Assumptions!$C$10)/((1+Assumptions!$C$11)^1) | E33: =C11*(Assumptions!$C$9/Assumptions!$C$10)/((1+Assumptions!$C$11)^2) | F33: =C11*(Assumptions!$C$9/Assumptions!$C$10)/((1+Assumptions!$C$11)^3) | G33: =C11*(Assumptions!$C$9/Assumptions!$C$10)/((1+Assumptions!$C$11)^4)
B34: Less: power/direct cost | C34: =-C12 | D34: =-C12 | E34: =-C12 | F34: =-C12 | G34: =-C12
B35: FCF (after maint capex) | C35: =IF((C33+C34)>0,(C33+C34)*(1-Assumptions!$C$14),(C33+C34)) | D35: =IF((D33+D34)>0,(D33+D34)*(1-Assumptions!$C$14),(D33+D34)) | E35: =IF((E33+E34)>0,(E33+E34)*(1-Assumptions!$C$14),(E33+E34)) | F35: =IF((F33+F34)>0,(F33+F34)*(1-Assumptions!$C$14),(F33+F34)) | G35: =IF((G33+G34)>0,(G33+G34)*(1-Assumptions!$C$14),(G33+G34))
B36: PV of FCF | C36: =C35/((1+Assumptions!$C$13)^1) | D36: =D35/((1+Assumptions!$C$13)^2) | E36: =E35/((1+Assumptions!$C$13)^3) | F36: =F35/((1+Assumptions!$C$13)^4) | G36: =G35/((1+Assumptions!$C$13)^5)
B37: Mining value (Σ PV, floored at 0) | C37: =MAX(0,SUM(C36:G36))
B39: BTC TREASURY & BRIDGE
B40: BTC treasury (×weighted price) | C40: =C13*Assumptions!$C$9/1000
B41: Less: overhead, cash SG&A capitalized | C41: =-(C14-C15)/Assumptions!$C$29 | D41: SG&A net of stock-comp
B42: INTRINSIC ENTERPRISE VALUE (operating) | C42: =C29+C37+C41
C43: =C42+C40+C17-C16-C18
B44: Intrinsic value / share ($) | C44: =C43*1000/(C19*1000000)
...
